Workbook

Sheet Tracking
A1: Period | B1: Time | C1: Strength | D1: Team | E1: Shooter | F1: Shot Type | G1: A1 | H1: A2 | I1: A3 | J1: A1 Zone | K1: A2 Zone | L1: A3 Zone | M1: SC? | N1: SOG? | O1: Screen? | P1: Rush? | Q1: Origin | R1: Context | S1: Oddman? | T1: G? | U1: State | V1: Goalie | W1: Game ID | X1: Date | Y1: Entry Type | Z1: Entry By | AA1: Defended by | AB1: Pass? | AC1: Lane | AD1: Dump recovered? | AE1: Chance? | AF1: Retrieval | AG1: Result | AH1: Pressure | AI1: Exit | AJ1: Result | AK1: Home | AL1: Road
A2: 1 | B2: 0.77708333 | C2: 5v5 | D2: COL | E2: 10 | F2: w | G2: 27 | J2: ol | M2: y | N2: y | P2: r | Q2: nz | R2: nz turnover | U2: 0 | V2: 29 | W2: 20984 | X2: 46087
A3: 1 | B3: 0.725 | C3: 5v4 | D3: COL | E3: 88 | F3: w | G3: 29 | H3: 88 | I3: 8 | J3: ol | K3: ol | L3: ol | M3: y | N3: y | Q3: oz | R3: oz faceoff | U3: 0 | V3: 29 | W3: 20984 | X3: 46087
A4: 1 | B4: 0.69375 | C4: 5v4 | D4: COL | E4: 88 | F4: w | G4: 29 | J4: oelr | M4: y | N4: y | U4: 0 | V4: 29 | W4: 20984 | X4: 46087
A5: 1 | B5: 0.68541667 | C5: 5v4 | D5: COL | E5: 8 | F5: w | G5: 29 | J5: opl | M5: y | N5: y | O5: y | T5: y | U5: 0 | V5: 29 | W5: 20984 | X5: 46087
A6: 1 | B6: 0.57083333 | C6: 5v4 | D6: DAL | E6: 21 | F6: o | G6: 53 | H6: 21 | I6: 4 | J6: ol | K6: oc | L6: ol | M6: y | N6: y | Q6: oz | R6: oz faceoff | U6: -1 | V6: 39 | W6: 20984 | X6: 46087
A7: 1 | B7: 0.54444444 | C7: 5v4 | D7: DAL | E7: 21 | F7: w | G7: 4 | H7: 21 | J7: ol | K7: or | U7: -1 | V7: 39 | W7: 20984 | X7: 46087
A8: 1 | B8: 0.53402778 | C8: 5v4 | D8: DAL | E8: 4 | F8: w | G8: 21 | J8: opl | N8: y | O8: y | T8: y | U8: -1 | V8: 39 | W8: 20984 | X8: 46087
A9: 1 | B9: 0.49652778 | C9: 5v5 | D9: DAL | E9: 6 | F9: W | G9: 46 | J9: or | N9: y | O9: y | P9: f | Q9: oz | U9: 0 | V9: 39 | W9: 20984 | X9: 46087
A10: 1 | B10: 0.47152778 | C10: 5v5 | D10: COL | E10: 11 | F10: W | G10: 20 | J10: oc | M10: y | N10: y | P10: f | Q10: oz | U10: 0 | V10: 29 | W10: 20984 | X10: 46087
A11: 1 | B11: 0.46666667 | C11: 5v5 | D11: COL | E11: 20 | F11: s | G11: 11 | J11: opl | N11: y | P11: f | Q11: oz | U11: 0 | V11: 29 | W11: 20984 | X11: 46087
A12: 1 | B12: 0.41041667 | C12: 5v5 | D12: DAL | E12: 11 | F12: T | G12: 21 | J12: s | M12: y | N12: y | O12: y | P12: f | Q12: oz | U12: 0 | V12: 39 | W12: 20984 | X12: 46087
A13: 1 | B13: 0.40625 | C13: 5v5 | D13: DAL | E13: 24 | F13: w | G13: 21 | J13: or | M13: y | P13: f | Q13: oz | U13: 0 | V13: 39 | W13: 20984 | X13: 46087
A14: 1 | B14: 0.40208333 | C14: 5v5 | D14: DAL | E14: 23 | F14: t | G14: 24 | J14: ol | M14: y | P14: f | Q14: oz | U14: 0 | V14: 39 | W14: 20984 | X14: 46087
A15: 1 | B15: 0.38958333 | C15: 5v5 | D15: DAL | E15: 53 | F15: W | G15: 4 | J15: ol | M15: Y | N15: Y | P15: f | Q15: oz | T15: y | U15: 0 | V15: 39 | W15: 20984 | X15: 46087
A16: 1 | B16: 0.37986111 | C16: 5v5 | D16: DAL | E16: 95 | F16: t | G16: 18 | H16: 5 | J16: or | K16: dsr | M16: y | N16: y | P16: r | Q16: dz | R16: dz exit | U16: 1 | V16: 39 | W16: 20984 | X16: 46087
A17: 1 | B17: 0.35625 | C17: 5v5 | D17: DAL | E17: 49 | F17: A | M17: y | N17: y | P17: f | Q17: oz | U17: 1 | V17: 39 | W17: 20984 | X17: 46087
A18: 1 | B18: 0.28333333 | C18: 5v5 | D18: DAL | E18: 5 | F18: w | G18: 49 | J18: or | N18: y | Q18: oz | R18: oz faceoff | U18: 1 | V18: 39 | W18: 20984 | X18: 46087
A19: 1 | B19: 0.23194444 | C19: 5v5 | D19: DAL | E19: 46 | F19: w | G19: 18 | J19: oelc | M19: Y | N19: Y | P19: f | Q19: oz | U19: 1 | V19: 39 | W19: 20984 | X19: 46087
A20: 1 | B20: 0.23125 | C20: 5v5 | D20: DAL | E20: 46 | F20: R | M20: Y | N20: Y | P20: f | Q20: oz | U20: 1 | V20: 39 | W20: 20984 | X20: 46087
A21: 1 | B21: 0.20902778 | C21: 5v5 | D21: DAL | E21: 53 | F21: T | G21: 5 | H21: 24 | J21: s | K21: opr | P21: f | Q21: oz | U21: 1 | V21: 39 | W21: 20984 | X21: 46087
A22: 1 | B22: 0.16388889 | C22: 5v5 | D22: DAL | E22: 49 | F22: w | G22: 22 | J22: oelc | M22: y | N22: y | P22: f | Q22: oz | T22: y | U22: 1 | V22: 39 | W22: 20984 | X22: 46087
A23: 1 | B23: 0.072222222 | C23: 5v4 | D23: COL | E23: 11 | F23: o | G23: 8 | H23: 88 | I23: 29 | J23: oc | K23: opl | L23: ol | M23: y | N23: y | U23: 1 | V23: 29 | W23: 20984 | X23: 46087
A24: 1 | B24: 0.067361111 | C24: 5v4 | D24: COL | E24: 92 | F24: t | G24: 29 | H24: 11 | J24: ol | K24: orrr | U24: 1 | V24: 29 | W24: 20984 | X24: 46087
A25: 1 | B25: 0.063194444 | C25: 5v4 | D25: COL | E25: 88 | F25: o | G25: 8 | H25: 11 | J25: oc | K25: opr | M25: y | N25: y | U25: 1 | V25: 29 | W25: 20984 | X25: 46087
A26: 1 | B26: 0.059027778 | C26: 5v4 | D26: COL | E26: 7 | F26: W | G26: 84 | H26: 20 | J26: oc | K26: ofp | M26: Y | N26: Y | Q26: oz | R26: oz faceoff | U26: 1 | V26: 29 | W26: 20984 | X26: 46087
A27: 1 | B27: 0.048611111 | C27: 5v4 | D27: COL | E27: 54 | F27: t | G27: 7 | H27: 13 | I27: 7 | J27: s | K27: opr | L27: oc | Q27: oz | R27: oz faceoff | U27: 1 | V27: 29 | W27: 20984 | X27: 46087
A28: 1 | B28: 0.0013888889 | C28: 5v4 | D28: COL | E28: 29 | F28: o | G28: 88 | H28: 8 | J28: oc | K28: opr | M28: y | N28: y | T28: y | U28: 1 | V28: 29 | W28: 20984 | X28: 46087
A29: 2 | B29: 0.78541667 | C29: 5v5 | D29: COL | E29: 13 | F29: w | G29: 7 | J29: nr | N29: y | P29: r | Q29: nz | R29: nz regroup | U29: 1 | V29: 29 | W29: 20984 | X29: 46087
A30: 2 | B30: 0.76805556 | C30: 5v5 | D30: COL | E30: 84 | F30: w | G30: 11 | J30: oelpr | P30: f | Q30: oz | U30: 1 | V30: 29 | W30: 20984 | X30: 46087
A31: 2 | B31: 0.75555556 | C31: 5v5 | D31: DAL | E31: 14 | F31: w | G31: 49 | J31: oelc | M31: y | N31: y | P31: f | Q31: oz | T31: y | U31: 1 | V31: 39 | W31: 20984 | X31: 46087
A32: 2 | B32: 0.70902778 | C32: 5v5 | D32: DAL | E32: 15 | F32: w | P32: f | Q32: oz | U32: 2 | V32: 39 | W32: 20984 | X32: 46087
A33: 2 | B33: 0.69166667 | C33: 5v5 | D33: COL | E33: 7 | F33: O | G33: 29 | H33: 88 | J33: opl | K33: nr | N33: Y | P33: r | Q33: dz | R33: controlled breakout | U33: 2 | V33: 29 | W33: 20984 | X33: 46087
A34: 2 | B34: 0.68472222 | C34: 5v5 | D34: COL | E34: 29 | F34: O | G34: 88 | J34: oc | M34: Y | N34: Y | P34: f | Q34: oz | U34: 2 | V34: 29 | W34: 20984 | X34: 46087
A35: 2 | B35: 0.65138889 | C35: 5v5 | D35: DAL | E35: 22 | F35: o | G35: 73 | H35: 22 | I35: 49 | J35: orrr | K35: or | L35: or | M35: y | N35: y | P35: f | Q35: oz | U35: 2 | V35: 39 | W35: 20984 | X35: 46087
A36: 2 | B36: 0.65069444 | C36: 5v5 | D36: DAL | E36: 49 | F36: o | G36: 22 | J36: oell | M36: y | N36: y | P36: f | Q36: oz | U36: 2 | V36: 39 | W36: 20984 | X36: 46087
A37: 2 | B37: 0.60069444 | C37: 5v5 | D37: DAL | E37: 18 | F37: o | G37: 6 | H37: 14 | I37: 6 | J37: orrl | K37: nl | L37: nc | M37: y | N37: y | P37: r | Q37: dz | R37: dz exit | U37: 2 | V37: 39 | W37: 20984 | X37: 46087
A38: 2 | B38: 0.53541667 | C38: 5v5 | D38: COL | E38: 92 | F38: w | G38: 8 | H38: 7 | J38: or | K38: ol | M38: y | N38: y | Q38: oz | R38: oz faceoff | U38: 2 | V38: 29 | W38: 20984 | X38: 46087
A39: 2 | B39: 0.49583333 | C39: 5v5 | D39: COL | E39: 88 | F39: w | G39: 29 | H39: 92 | I39: 7 | J39: oc | K39: oc | L39: nl | M39: y | N39: y | P39: r | Q39: nz | R39: nz regroup | T39: y | U39: 2 | V39: 29 | W39: 20984 | X39: 46087
A40: 2 | B40: 0.42986111 | C40: 5v4 | D40: COL | E40: 20 | F40: w | G40: 29 | J40: orrl | M40: y | N40: y | U40: 1 | V40: 29 | W40: 20984 | X40: 46087
...

Sheet Player List
A1: # | B1: Player | C1: Team | D1: Pos. | E1: 5v5 TOI | F1: Year | G1: Game | H1: Shots | I1: Shots On Goal | J1: Chances | K1: Passes | L1: Primary Shot Assists | M1: Secondary Assists | N1: Tertiary Assists | O1: Chance Assists | P1: Home Plate | Q1: Low-to-High | R1: Behind Net | S1: Center Lane Assists | T1: NZ Assist | U1: DZ Assist | V1: Shots off Rush | W1: Assists off Rush | X1: Shots off Forecheck or Cycle | Y1: Assists off Forecheck | Z1: Shots off Cycle | AA1: Assists off Cycle | AB1: Shots off HD Passes | AC1: Zone Entries | AD1: Carries | AE1: Failed Entries | AF1: Entries w/ Passing Play | AG1: Recoveries | AH1: Carries w/ Chances | AI1: Dump-in Chances | AJ1: Forecheck Pressures | AK1: DZ Puck Touches | AL1: DZ Retrievals | AM1: Zone Exits | AN1: Exits w/ Possession | AO1: Carried Exits | AP1: Passed Exits | AQ1: Clears | AR1: Missed Passes | AS1: Retrievals Leading to Exits | AT1: Botched Retrievals | AU1: Exchanges | AV1: Failed Exit | AW1: Rushed Exits | AX1: Second Touch Exits | AY1: Targets | AZ1: Carries | BA1: Denials | BB1: Passes Allowed | BC1: Carries w/ Chance Against | BD1: Dump-in w/ Chance Against | BE1: 5v4 Entries | BF1: 5v4 Carries | BG1: 5v4 Setups | BH1: 4v5 Entries | BI1: 4v5 Carry Denials | BJ1: 5v4 Shots | BK1: 5v4 Passes | BL1: 5v4 Primary Setups | BM1: 5v4 Chances | BN1: 5v4 Chance Setups | BO1: 5v4 Cross-Slot | BP1: 5v4 Low-to-High | BQ1: 5v4 Goal Line | BR1: One-timer | BS1: Rebounds | BT1: Deflections | BU1: One-timer Assists | BV1: Rebound Assists | BW1: Deflection Assists | BX1: OZ | BY1: NZ | BZ1: DZ | CA1: OZ Assists | CB1: NZ Assists | CC1: DZ Assists | CD1: DZ Retrieval | CE1: DZ Counter | CF1: NZ Turnover | CG1: NZ Regroup | CH1: NZ Reload | CI1: DZ Controlled Breakout | CJ1: Microstat Game Score | CK1: Offense | CL1: Zone Entries | CM1: Entry Defense | CN1: Exits | CO1: Forechecking | CP1: Special Teams | CQ1: 5v5 Game Score
A2: 73 | B2: Adam Erne | C2: DAL | D2: L | E2: 10.383333 | F2: 2025-26 | G2: 3/6/2026 DAL vs. COL | H2: =COUNTIFS(Tracking!E:E,A2,Tracking!D:D,C2,Tracking!C:C,"5v5") | I2: =COUNTIFS(Tracking!E:E,A2,Tracking!D:D,C2,Tracking!N:N,"y",Tracking!C:C,"5v5") | J2: =COUNTIFS(Tracking!E:E,A2,Tracking!D:D,C2,Tracking!M:M,"y",Tracking!C:C,"5v5") | K2: =L2+M2+N2 | L2: =COUNTIFS(Tracking!G:G,A2,Tracking!D:D,C2,Tracking!C:C,"5v5") | M2: =COUNTIFS(Tracking!H:H,A2,Tracking!D:D,C2,Tracking!C:C,"5v5") | N2: =COUNTIFS(Tracking!I:I,A2,Tracking!D:D,C2,Tracking!C:C,"5v5") | O2: =COUNTIFS(Tracking!G:G,A2,Tracking!D:D,C2,Tracking!C:C,"5v5",Tracking!M:M,"y") | P2: =COUNTIFS(Tracking!G:G,A2,Tracking!D:D,C2,Tracking!C:C,"5v5",Tracking!J:J,"orrl")+COUNTIFS(Tracking!G:G,A2,Tracking!D:D,C2,Tracking!C:C,"5v5",Tracking!J:J,"orrc")+COUNTIFS(Tracking!G:G,A2,Tracking!D:D,C2,Tracking!C:C,"5v5",Tracking!J:J,"orrr")+COUNTIFS(Tracking!G:G,A2,Tracking!D:D,C2,Tracking!C:C,"5v5",Tracking!J:J,"oelrrl")+COUNTIFS(Tracking!G:G,A2,Tracking!D:D,C2,Tracking!C:C,"5v5",Tracking!J:J,"oelrrc")+COUNTIFS(Tracking!G:G,A2,Tracking!D:D,C2,Tracking!C:C,"5v5",Tracking!J:J,"oelrrr") | Q2: =COUNTIFS(Tracking!G:G,A2,Tracking!D:D,C2,Tracking!C:C,"5v5",Tracking!J:J,"opl")+COUNTIFS(Tracking!G:G,A2,Tracking!D:D,C2,Tracking!C:C,"5v5",Tracking!J:J,"opc")+COUNTIFS(Tracking!G:G,A2,Tracking!D:D,C2,Tracking!C:C,"5v5",Tracking!J:J,"opr")+COUNTIFS(Tracking!G:G,A2,Tracking!D:D,C2,Tracking!C:C,"5v5",Tracking!J:J,"oelpl")+COUNTIFS(Tracking!G:G,A2,Tracking!D:D,C2,Tracking!C:C,"5v5",Tracking!J:J,"oelpc")+COUNTIFS(Tracking!G:G,A2,Tracking!D:D,C2,Tracking!C:C,"5v5",Tracking!J:J,"oelpr") | R2: =COUNTIFS(Tracking!G:G,A2,Tracking!D:D,C2,Tracking!C:C,"5v5",Tracking!J:J,"oell")+COUNTIFS(Tracking!G:G,A2,Tracking!D:D,C2,Tracking!C:C,"5v5",Tracking!J:J,"oelc")+COUNTIFS(Tracking!G:G,A2,Tracking!D:D,C2,Tracking!C:C,"5v5",Tracking!J:J,"oelr") | S2: =COUNTIFS(Tracking!G:G,A2,Tracking!D:D,C2,Tracking!C:C,"5v5",Tracking!J:J,"oc")+COUNTIFS(Tracking!G:G,A2,Tracking!D:D,C2,Tracking!C:C,"5v5",Tracking!J:J,"orrc")+COUNTIFS(Tracking!G:G,A2,Tracking!D:D,C2,Tracking!C:C,"5v5",Tracking!J:J,"oelc") | T2: =COUNTIFS(Tracking!G:G,A2,Tracking!D:D,C2,Tracking!C:C,"5v5",Tracking!J:J,"nl")+COUNTIFS(Tracking!G:G,A2,Tracking!D:D,C2,Tracking!C:C,"5v5",Tracking!J:J,"nc")+COUNTIFS(Tracking!G:G,A2,Tracking!D:D,C2,Tracking!C:C,"5v5",Tracking!J:J,"nr")+COUNTIFS(Tracking!G:G,A2,Tracking!D:D,C2,Tracking!C:C,"5v5",Tracking!J:J,"nsl")+COUNTIFS(Tracking!G:G,A2,Tracking!D:D,C2,Tracking!C:C,"5v5",Tracking!J:J,"nsc")+COUNTIFS(Tracking!G:G,A2,Tracking!D:D,C2,Tracking!C:C,"5v5",Tracking!J:J,"nsr")+COUNTIFS(Tracking!H:H,A2,Tracking!D:D,C2,Tracking!C:C,"5v5",Tracking!K:K,"nl")+COUNTIFS(Tracking!H:H,A2,Tracking!D:D,C2,Tracking!C:C,"5v5",Tracking!K:K,"nc")+COUNTIFS(Tracking!H:H,A2,Tracking!D:D,C2,Tracking!C:C,"5v5",Tracking!K:K,"nr")+COUNTIFS(Tracking!H:H,A2,Tracking!D:D,C2,Tracking!C:C,"5v5",Tracking!K:K,"nsl")+COUNTIFS(Tracking!H:H,A2,Tracking!D:D,C2,Tracking!C:C,"5v5",Tracking!K:K,"nsc")+COUNTIFS(Tracking!H:H,A2,Tracking!D:D,C2,Tracking!C:C,"5v5",Tracking!K:K,"nsr")+COUNTIFS(Tracking!I:I,A2,Tracking!D:D,C2,Tracking!C:C,"5v5",Tracking!L:L,"nl")+COUNTIFS(Tracking!I:I,A2,Tracking!D:D,C2,Tracking!C:C,"5v5",Tracking!L:L,"nc")+COUNTIFS(Tracking!I:I,A2,Tracking!D:D,C2,Tracking!C:C,"5v5",Tracking!L:L,"nr")+COUNTIFS(Tracking!I:I,A2,Tracking!D:D,C2,Tracking!C:C,"5v5",Tracking!L:L,"nsl")+COUNTIFS(Tracking!I:I,A2,Tracking!D:D,C2,Tracking!C:C,"5v5",Tracking!L:L,"nsc")+COUNTIFS(Tracking!I:I,A2,Tracking!D:D,C2,Tracking!C:C,"5v5",Tracking!L:L,"nsr") | U2: =COUNTIFS(Tracking!G:G,A2,Tracking!D:D,C2,Tracking!C:C,"5v5",Tracking!J:J,"dl")+COUNTIFS(Tracking!G:G,A2,Tracking!D:D,C2,Tracking!C:C,"5v5",Tracking!J:J,"dc")+COUNTIFS(Tracking!G:G,A2,Tracking!D:D,C2,Tracking!C:C,"5v5",Tracking!J:J,"dr")+COUNTIFS(Tracking!G:G,A2,Tracking!D:D,C2,Tracking!C:C,"5v5",Tracking!J:J,"dsl")+COUNTIFS(Tracking!G:G,A2,Tracking!D:D,C2,Tracking!C:C,"5v5",Tracking!J:J,"dsc")+COUNTIFS(Tracking!G:G,A2,Tracking!D:D,C2,Tracking!C:C,"5v5",Tracking!J:J,"dsr")+COUNTIFS(Tracking!H:H,A2,Tracking!D:D,C2,Tracking!C:C,"5v5",Tracking!K:K,"dl")+COUNTIFS(Tracking!H:H,A2,Tracking!D:D,C2,Tracking!C:C,"5v5",Tracking!K:K,"dc")+COUNTIFS(Tracking!H:H,A2,Tracking!D:D,C2,Tracking!C:C,"5v5",Tracking!K:K,"dr")+COUNTIFS(Tracking!H:H,A2,Tracking!D:D,C2,Tracking!C:C,"5v5",Tracking!K:K,"dsl")+COUNTIFS(Tracking!H:H,A2,Tracking!D:D,C2,Tracking!C:C,"5v5",Tracking!K:K,"dsc")+COUNTIFS(Tracking!H:H,A2,Tracking!D:D,C2,Tracking!C:C,"5v5",Tracking!K:K,"dsr")+COUNTIFS(Tracking!I:I,A2,Tracking!D:D,C2,Tracking!C:C,"5v5",Tracking!L:L,"dl")+COUNTIFS(Tracking!I:I,A2,Tracking!D:D,C2,Tracking!C:C,"5v5",Tracking!L:L,"dc")+COUNTIFS(Tracking!I:I,A2,Tracking!D:D,C2,Tracking!C:C,"5v5",Tracking!L:L,"dr")+COUNTIFS(Tracking!I:I,A2,Tracking!D:D,C2,Tracking!C:C,"5v5",Tracking!L:L,"dsl")+COUNTIFS(Tracking!I:I,A2,Tracking!D:D,C2,Tracking!C:C,"5v5",Tracking!L:L,"dsc")+COUNTIFS(Tracking!I:I,A2,Tracking!D:D,C2,Tracking!C:C,"5v5",Tracking!L:L,"dsr") | V2: =COUNTIFS(Tracking!E:E,A2,Tracking!D:D,C2,Tracking!C:C,"5v5",Tracking!P:P,"r") | W2: =COUNTIFS(Tracking!G:G,A2,Tracking!D:D,C2,Tracking!C:C,"5v5",Tracking!P:P,"r")+COUNTIFS(Tracking!H:H,A2,Tracking!D:D,C2,Tracking!C:C,"5v5",Tracking!P:P,"r")+COUNTIFS(Tracking!I:I,A2,Tracking!D:D,C2,Tracking!C:C,"5v5",Tracking!P:P,"r") | X2: =COUNTIFS(Tracking!E:E,A2,Tracking!D:D,C2,Tracking!C:C,"5v5",Tracking!P:P,"f") | Y2: =COUNTIFS(Tracking!G:G,A2,Tracking!D:D,C2,Tracking!C:C,"5v5",Tracking!P:P,"f")+COUNTIFS(Tracking!H:H,A2,Tracking!D:D,C2,Tracking!C:C,"5v5",Tracking!P:P,"f")+COUNTIFS(Tracking!I:I,A2,Tracking!D:D,C2,Tracking!C:C,"5v5",Tracking!P:P,"f") | Z2: =COUNTIFS(Tracking!E:E,A2,Tracking!D:D,C2,Tracking!C:C,"5v5",Tracking!P:P,"c") | AA2: =COUNTIFS(Tracking!G:G,A2,Tracking!D:D,C2,Tracking!C:C,"5v5",Tracking!P:P,"c")+COUNTIFS(Tracking!H:H,A2,Tracking!D:D,C2,Tracking!C:C,"5v5",Tracking!P:P,"f")+COUNTIFS(Tracking!I:I,A2,Tracking!D:D,C2,Tracking!C:C,"5v5",Tracking!P:P,"f") | AB2: =COUNTIFS(Tracking!E:E,A2,Tracking!D:D,C2,Tracking!C:C,"5v5",Tracking!J:J,"orrl")+COUNTIFS(Tracking!E:E,A2,Tracking!D:D,C2,Tracking!C:C,"5v5",Tracking!J:J,"orrc")+COUNTIFS(Tracking!E:E,A2,Tracking!D:D,C2,Tracking!C:C,"5v5",Tracking!J:J,"orrr")+COUNTIFS(Tracking!E:E,A2,Tracking!D:D,C2,Tracking!C:C,"5v5",Tracking!J:J,"oell")+COUNTIFS(Tracking!E:E,A2,Tracking!D:D,C2,Tracking!C:C,"5v5",Tracking!J:J,"oelc")+COUNTIFS(Tracking!E:E,A2,Tracking!D:D,C2,Tracking!C:C,"5v5",Tracking!J:J,"oelr") | AC2: =COUNTIFS(Tracking!Z:Z,A2&C2,Tracking!C:C,"5v5")-AE2 | AD2: =COUNTIFS(Tracking!Z:Z,A2&C2,Tracking!C:C,"5v5",Tracking!Y:Y,"C") | AE2: =COUNTIFS(Tracking!Z:Z,A2&C2,Tracking!C:C,"5v5",Tracking!Y:Y,"F") | AF2: =COUNTIFS(Tracking!Z:Z,A2&C2,Tracking!C:C,"5v5",Tracking!Y:Y,"C",Tracking!AB:AB,"Y") | AG2: =COUNTIFS(Tracking!AD:AD,A2&C2,Tracking!C:C,"5v5") | AH2: =COUNTIFS(Tracking!Z:Z,A2&C2,Tracking!C:C,"5v5",Tracking!Y:Y,"C",Tracking!AE:AE,"Y") | AI2: =COUNTIFS(Tracking!Z:Z,A2&C2,Tracking!C:C,"5v5",Tracking!Y:Y,"D",Tracking!AE:AE,"Y") | AJ2: =COUNTIFS(Tracking!AH:AH,A2&C2) | AK2: =COUNTIFS(Tracking!AI:AI,A2&C2,Tracking!C:C,"5v5")+AL2 | AL2: =COUNTIFS(Tracking!AF:AF,A2&C2,Tracking!C:C,"5v5")-AT2 | AM2: =COUNTIFS(Tracking!AF:AF,A2&C2,Tracking!C:C,"5v5",Tracking!AG:AG,"CLE")+COUNTIFS(Tracking!AF:AF,A2&C2,Tracking!C:C,"5v5",Tracking!AG:AG,"CEX")+COUNTIFS(Tracking!AF:AF,A2&C2,Tracking!C:C,"5v5",Tracking!AG:AG,"PEX")+COUNTIFS(Tracking!AI:AI,A2&C2,Tracking!C:C,"5v5",Tracking!AJ:AJ,"CLE")+COUNTIFS(Tracking!AI:AI,A2&C2,Tracking!C:C,"5v5",Tracking!AJ:AJ,"CEX")+COUNTIFS(Tracking!AI:AI,A2&C2,Tracking!C:C,"5v5",Tracking!AJ:AJ,"PEX") | AN2: =COUNTIFS(Tracking!AF:AF,A2&C2,Tracking!C:C,"5v5",Tracking!AG:AG,"CEX")+COUNTIFS(Tracking!AF:AF,A2&C2,Tracking!C:C,"5v5",Tracking!AG:AG,"PEX")+COUNTIFS(Tracking!AI:AI,A2&C2,Tracking!C:C,"5v5",Tracking!AJ:AJ,"CEX")+COUNTIFS(Tracking!AI:AI,A2&C2,Tracking!C:C,"5v5",Tracking!AJ:AJ,"PEX") | AO2: =COUNTIFS(Tracking!AF:AF,A2&C2,Tracking!C:C,"5v5",Tracking!AG:AG,"CEX")+COUNTIFS(Tracking!AI:AI,A2&C2,Tracking!C:C,"5v5",Tracking!AJ:AJ,"CEX") | AP2: =COUNTIFS(Tracking!AF:AF,A2&C2,Tracking!C:C,"5v5",Tracking!AG:AG,"PEX") | AQ2: =COUNTIFS(Tracking!AF:AF,A2&C2,Tracking!C:C,"5v5",Tracking!AG:AG,"CLE")+COUNTIFS(Tracking!AI:AI,A2&C2,Tracking!C:C,"5v5",Tracking!AJ:AJ,"CLE") | AR2: =COUNTIFS(Tracking!AF:AF,A2&C2,Tracking!C:C,"5v5",Tracking!AG:AG,"MEX") | AS2: =COUNTIFS(Tracking!AF:AF,A2&C2,Tracking!C:C,"5v5",Tracking!AJ:AJ,"CEX")+COUNTIFS(Tracking!AF:AF,A2&C2,Tracking!C:C,"5v5",Tracking!AJ:AJ,"PEX")+COUNTIFS(Tracking!AF:AF,A2&C2,Tracking!C:C,"5v5",Tracking!AJ:AJ,"CLE")+COUNTIFS(Tracking!AF:AF,A2&C2,Tracking!C:C,"5v5",Tracking!AG:AG,"CEX")+COUNTIFS(Tracking!AF:AF,A2&C2,Tracking!C:C,"5v5",Tracking!AG:AG,"PEX") | AT2: =COUNTIFS(Tracking!AF:AF,A2&C2,Tracking!C:C,"5v5",Tracking!AG:AG,"BOT")+COUNTIFS(Tracking!AF:AF,A2&C2,Tracking!C:C,"5v5",Tracking!AG:AG,"FEX") | AU2: =COUNTIFS(Tracking!AF:AF,A2&C2,Tracking!C:C,"5v5",Tracking!AG:AG,"EXC") | AV2: =COUNTIFS(Tracking!AF:AF,A2&C2,Tracking!C:C,"5v5",Tracking!AG:AG,"FEX")+COUNTIFS(Tracking!AI:AI,A2&C2,Tracking!C:C,"5v5",Tracking!AJ:AJ,"FEX") | AW2: =COUNTIFS(Tracking!AF:AF,A2&C2,Tracking!C:C,"5v5",Tracking!AG:AG,"CLE")+COUNTIFS(Tracking!AF:AF,A2&C2,Tracking!C:C,"5v5",Tracking!AG:AG,"CEX")+COUNTIFS(Tracking!AF:AF,A2&C2,Tracking!C:C,"5v5",Tracking!AG:AG,"PEX") | AX2: =COUNTIFS(Tracking!AI:AI,A2&C2,Tracking!C:C,"5v5",Tracking!AJ:AJ,"CLE")+COUNTIFS(Tracking!AI:AI,A2&C2,Tracking!C:C,"5v5",Tracking!AJ:AJ,"CEX")+COUNTIFS(Tracking!AI:AI,A2&C2,Tracking!C:C,"5v5",Tracking!AJ:AJ,"PEX") | AY2: =COUNTIFS(Tracking!AA:AA,A2&C2,Tracking!C:C,"5v5") | AZ2: =COUNTIFS(Tracking!AA:AA,A2&C2,Tracking!C:C,"5v5",Tracking!Y:Y,"C") | BA2: =COUNTIFS(Tracking!AA:AA,A2&C2,Tracking!C:C,"5v5",Tracking!Y:Y,"F") | BB2: =COUNTIFS(Tracking!AA:AA,A2&C2,Tracking!C:C,"5v5",Tracking!AB:AB,"Y") | BC2: =COUNTIFS(Tracking!AA:AA,A2&C2,Tracking!C:C,"5v5",Tracking!Y:Y,"C",Tracking!AE:AE,"Y") | BD2: =COUNTIFS(Tracking!AA:AA,A2&C2,Tracking!C:C,"5v5",Tracking!Y:Y,"D",Tracking!AE:AE,"Y") | BE2: =COUNTIFS(Tracking!Z:Z,A2&C2,Tracking!C:C,"5v4") | BF2: =COUNTIFS(Tracking!Z:Z,A2&C2,Tracking!C:C,"5v4",Tracking!Y:Y,"C") | BG2: =COUNTIFS(Tracking!Z:Z,A2&C2,Tracking!C:C,"5v4",Tracking!AB:AB,"Y") | BH2: =COUNTIFS(Tracking!Z:Z,A2&C2,Tracking!C:C,"4v5") | BI2: =COUNTIFS(Tracking!AA:AA,A2&C2,Tracking!C:C,"5v4",Tracking!Y:Y,"D")+COUNTIFS(Tracking!AA:AA,A2&C2,Tracking!C:C,"5v4",Tracking!Y:Y,"F") | BJ2: =COUNTIFS(Tracking!E:E,A2,Tracking!D:D,C2,Tracking!C:C,"5v4") | BK2: =COUNTIFS(Tracking!G:G,A2,Tracking!D:D,C2,Tracking!C:C,"5v4")+COUNTIFS(Tracking!H:H,A2,Tracking!D:D,C2,Tracking!C:C,"5v4")+COUNTIFS(Tracking!I:I,A2,Tracking!D:D,C2,Tracking!C:C,"5v4") | BL2: =COUNTIFS(Tracking!G:G,A2,Tracking!D:D,C2,Tracking!C:C,"5v4") | BM2: =COUNTIFS(Tracking!E:E,A2,Tracking!D:D,C2,Tracking!C:C,"5v4",Tracking!M:M,"Y") | BN2: =COUNTIFS(Tracking!G:G,A2,Tracking!D:D,C2,Tracking!C:C,"5v4",Tracking!M:M,"Y") | BO2: =COUNTIFS(Tracking!G:G,A2,Tracking!D:D,C2,Tracking!J:J,"orrl",Tracking!C:C,"5v4")+COUNTIFS(Tracking!G:G,A2,Tracking!D:D,C2,Tracking!J:J,"orrc",Tracking!C:C,"5v4")+COUNTIFS(Tracking!G:G,A2,Tracking!D:D,C2,Tracking!J:J,"orrr",Tracking!C:C,"5v4") | BP2: =COUNTIFS(Tracking!G:G,A2,Tracking!D:D,C2,Tracking!C:C,"5v4",Tracking!J:J,"opl")+COUNTIFS(Tracking!G:G,A2,Tracking!D:D,C2,Tracking!C:C,"5v4",Tracking!J:J,"opc")+COUNTIFS(Tracking!G:G,A2,Tracking!D:D,C2,Tracking!C:C,"5v4",Tracking!J:J,"opr")+COUNTIFS(Tracking!G:G,A2,Tracking!D:D,C2,Tracking!C:C,"5v4",Tracking!J:J,"oelpl")+COUNTIFS(Tracking!G:G,A2,Tracking!D:D,C2,Tracking!C:C,"5v4",Tracking!J:J,"oelpc")+COUNTIFS(Tracking!G:G,A2,Tracking!D:D,C2,Tracking!C:C,"5v4",Tracking!J:J,"oelpr") | BQ2: =COUNTIFS(Tracking!G:G,A2,Tracking!D:D,C2,Tracking!C:C,"5v4",Tracking!J:J,"oell")+COUNTIFS(Tracking!G:G,A2,Tracking!D:D,C2,Tracking!C:C,"5v4",Tracking!J:J,"oelc")+COUNTIFS(Tracking!G:G,A2,Tracking!D:D,C2,Tracking!C:C,"5v4",Tracking!J:J,"oelr") | BR2: =COUNTIFS(Tracking!E:E,A2,Tracking!D:D,C2,Tracking!C:C,"5v5",Tracking!F:F,"o") | BS2: =COUNTIFS(Tracking!E:E,A2,Tracking!D:D,C2,Tracking!C:C,"5v5",Tracking!F:F,"r") | BT2: =COUNTIFS(Tracking!E:E,A2,Tracking!D:D,C2,Tracking!C:C,"5v5",Tracking!F:F,"t") | BU2: =COUNTIFS(Tracking!G:G,A2,Tracking!D:D,C2,Tracking!C:C,"5v5",Tracking!F:F,"o") | BV2: =COUNTIFS(Tracking!E:E,A1,Tracking!D:D,C2,Tracking!C:C,"5v5",Tracking!F:F,"r") | BW2: =COUNTIFS(Tracking!G:G,A2,Tracking!D:D,C2,Tracking!C:C,"5v5",Tracking!F:F,"T") | BX2: =COUNTIFS(Tracking!E:E,A2,Tracking!D:D,C2,Tracking!C:C,"5v5",Tracking!Q:Q,"OZ") | BY2: =COUNTIFS(Tracking!E:E,A2,Tracking!D:D,C2,Tracking!C:C,"5v5",Tracking!Q:Q,"nZ") | BZ2: =COUNTIFS(Tracking!E:E,A2,Tracking!D:D,C2,Tracking!C:C,"5v5",Tracking!Q:Q,"dZ") | CA2: =COUNTIFS(Tracking!G:G,A2,Tracking!D:D,C2,Tracking!C:C,"5v5",Tracking!Q:Q,"OZ")+COUNTIFS(Tracking!H:H,A2,Tracking!D:D,C2,Tracking!C:C,"5v5",Tracking!Q:Q,"OZ")+COUNTIFS(Tracking!I:I,A2,Tracking!D:D,C2,Tracking!C:C,"5v5",Tracking!Q:Q,"OZ") | CB2: =COUNTIFS(Tracking!G:G,A2,Tracking!D:D,C2,Tracking!C:C,"5v5",Tracking!Q:Q,"nZ")+COUNTIFS(Tracking!H:H,A2,Tracking!D:D,C2,Tracking!C:C,"5v5",Tracking!Q:Q,"nZ")+COUNTIFS(Tracking!I:I,A2,Tracking!D:D,C2,Tracking!C:C,"5v5",Tracking!Q:Q,"nZ") | CC2: =COUNTIFS(Tracking!G:G,A2,Tracking!D:D,C2,Tracking!C:C,"5v5",Tracking!Q:Q,"dZ")+COUNTIFS(Tracking!H:H,A2,Tracking!D:D,C2,Tracking!C:C,"5v5",Tracking!Q:Q,"dZ")+COUNTIFS(Tracking!I:I,A2,Tracking!D:D,C2,Tracking!C:C,"5v5",Tracking!Q:Q,"dZ") | CD2: =COUNTIFS(Tracking!E:E,A2,Tracking!D:D,C2,Tracking!C:C,"5v5",Tracking!R:R,"dz exit") | CE2: =COUNTIFS(Tracking!E:E,A2,Tracking!D:D,C2,Tracking!C:C,"5v5",Tracking!R:R,"dz counter") | CF2: =COUNTIFS(Tracking!E:E,A2,Tracking!D:D,C2,Tracking!C:C,"5v5",Tracking!R:R,"nz turnover") | CG2: =COUNTIFS(Tracking!E:E,A2,Tracking!D:D,C2,Tracking!C:C,"5v5",Tracking!R:R,"nz regroup") | CH2: =COUNTIFS(Tracking!E:E,A2,Tracking!D:D,C2,Tracking!C:C,"5v5",Tracking!R:R,"nz reload") | CI2: =COUNTIFS(Tracking!E:E,A2,Tracking!D:D,C2,Tracking!C:C,"5v5",Tracking!R:R,"controlled breakout") | CJ2: =CK2+CL2+CM2+CN2+CO2+CP2 | CK2: =(0.075*H2)+(0.07*L2)+(0.055*M2)+(0.055*N2)+(0.095*J2)+(0.09*O2)+(0.05*P2)+(0.05*R2)+(0.05*S2)+(0.05*AB2) | CL2: =(0.045*AD2)-(0.045*AE2)+(0.055*AH2)+(0.035*AI2) | CM2: =(0.025*(AY2-AZ2))+(0.035*BA2)-(0.015*BB2)-(0.015*BC2)+(0.015*(AY2-(BD2+BC2))) | CN2: =(0.035*AN2)+(0.025*AS2)-(0.035*AT2)-(0.035*AV2) | CO2: =(0.015*AJ2)+(0.045*AG2) | CP2: =(0.055*BM2)+(0.055*BN2)+(0.035*BO2)+(0.035*BQ2)+(0.055*BH2)+(0.035*BI2)+(0.035*BG2) | CQ2: =CK2+CL2+CM2+CN2+CO2
A3: 15 | B3: Colin Blackwell | C3: DAL | D3: C | E3: 7.8166667 | F3: 2025-26 | G3: 3/6/2026 DAL vs. COL | H3: =COUNTIFS(Tracking!E:E,A3,Tracking!D:D,C3,Tracking!C:C,"5v5") | I3: =COUNTIFS(Tracking!E:E,A3,Tracking!D:D,C3,Tracking!N:N,"y",Tracking!C:C,"5v5") | J3: =COUNTIFS(Tracking!E:E,A3,Tracking!D:D,C3,Tracking!M:M,"y",Tracking!C:C,"5v5") | K3: =L3+M3+N3 | L3: =COUNTIFS(Tracking!G:G,A3,Tracking!D:D,C3,Tracking!C:C,"5v5") | M3: =COUNTIFS(Tracking!H:H,A3,Tracking!D:D,C3,Tracking!C:C,"5v5") | N3: =COUNTIFS(Tracking!I:I,A3,Tracking!D:D,C3,Tracking!C:C,"5v5") | O3: =COUNTIFS(Tracking!G:G,A3,Tracking!D:D,C3,Tracking!C:C,"5v5",Tracking!M:M,"y") | P3: =COUNTIFS(Tracking!G:G,A3,Tracking!D:D,C3,Tracking!C:C,"5v5",Tracking!J:J,"orrl")+COUNTIFS(Tracking!G:G,A3,Tracking!D:D,C3,Tracking!C:C,"5v5",Tracking!J:J,"orrc")+COUNTIFS(Tracking!G:G,A3,Tracking!D:D,C3,Tracking!C:C,"5v5",Tracking!J:J,"orrr")+COUNTIFS(Tracking!G:G,A3,Tracking!D:D,C3,Tracking!C:C,"5v5",Tracking!J:J,"oelrrl")+COUNTIFS(Tracking!G:G,A3,Tracking!D:D,C3,Tracking!C:C,"5v5",Tracking!J:J,"oelrrc")+COUNTIFS(Tracking!G:G,A3,Tracking!D:D,C3,Tracking!C:C,"5v5",Tracking!J:J,"oelrrr") | Q3: =COUNTIFS(Tracking!G:G,A3,Tracking!D:D,C3,Tracking!C:C,"5v5",Tracking!J:J,"opl")+COUNTIFS(Tracking!G:G,A3,Tracking!D:D,C3,Tracking!C:C,"5v5",Tracking!J:J,"opc")+COUNTIFS(Tracking!G:G,A3,Tracking!D:D,C3,Tracking!C:C,"5v5",Tracking!J:J,"opr")+COUNTIFS(Tracking!G:G,A3,Tracking!D:D,C3,Tracking!C:C,"5v5",Tracking!J:J,"oelpl")+COUNTIFS(Tracking!G:G,A3,Tracking!D:D,C3,Tracking!C:C,"5v5",Tracking!J:J,"oelpc")+COUNTIFS(Tracking!G:G,A3,Tracking!D:D,C3,Tracking!C:C,"5v5",Tracking!J:J,"oelpr") | R3: =COUNTIFS(Tracking!G:G,A3,Tracking!D:D,C3,Tracking!C:C,"5v5",Tracking!J:J,"oell")+COUNTIFS(Tracking!G:G,A3,Tracking!D:D,C3,Tracking!C:C,"5v5",Tracking!J:J,"oelc")+COUNTIFS(Tracking!G:G,A3,Tracking!D:D,C3,Tracking!C:C,"5v5",Tracking!J:J,"oelr") | S3: =COUNTIFS(Tracking!G:G,A3,Tracking!D:D,C3,Tracking!C:C,"5v5",Tracking!J:J,"oc")+COUNTIFS(Tracking!G:G,A3,Tracking!D:D,C3,Tracking!C:C,"5v5",Tracking!J:J,"orrc")+COUNTIFS(Tracking!G:G,A3,Tracking!D:D,C3,Tracking!C:C,"5v5",Tracking!J:J,"oelc") | T3: =COUNTIFS(Tracking!G:G,A3,Tracking!D:D,C3,Tracking!C:C,"5v5",Tracking!J:J,"nl")+COUNTIFS(Tracking!G:G,A3,Tracking!D:D,C3,Tracking!C:C,"5v5",Tracking!J:J,"nc")+COUNTIFS(Tracking!G:G,A3,Tracking!D:D,C3,Tracking!C:C,"5v5",Tracking!J:J,"nr")+COUNTIFS(Tracking!G:G,A3,Tracking!D:D,C3,Tracking!C:C,"5v5",Tracking!J:J,"nsl")+COUNTIFS(Tracking!G:G,A3,Tracking!D:D,C3,Tracking!C:C,"5v5",Tracking!J:J,"nsc")+COUNTIFS(Tracking!G:G,A3,Tracking!D:D,C3,Tracking!C:C,"5v5",Tracking!J:J,"nsr")+COUNTIFS(Tracking!H:H,A3,Tracking!D:D,C3,Tracking!C:C,"5v5",Tracking!K:K,"nl")+COUNTIFS(Tracking!H:H,A3,Tracking!D:D,C3,Tracking!C:C,"5v5",Tracking!K:K,"nc")+COUNTIFS(Tracking!H:H,A3,Tracking!D:D,C3,Tracking!C:C,"5v5",Tracking!K:K,"nr")+COUNTIFS(Tracking!H:H,A3,Tracking!D:D,C3,Tracking!C:C,"5v5",Tracking!K:K,"nsl")+COUNTIFS(Tracking!H:H,A3,Tracking!D:D,C3,Tracking!C:C,"5v5",Tracking!K:K,"nsc")+COUNTIFS(Tracking!H:H,A3,Tracking!D:D,C3,Tracking!C:C,"5v5",Tracking!K:K,"nsr")+COUNTIFS(Tracking!I:I,A3,Tracking!D:D,C3,Tracking!C:C,"5v5",Tracking!L:L,"nl")+COUNTIFS(Tracking!I:I,A3,Tracking!D:D,C3,Tracking!C:C,"5v5",Tracking!L:L,"nc")+COUNTIFS(Tracking!I:I,A3,Tracking!D:D,C3,Tracking!C:C,"5v5",Tracking!L:L,"nr")+COUNTIFS(Tracking!I:I,A3,Tracking!D:D,C3,Tracking!C:C,"5v5",Tracking!L:L,"nsl")+COUNTIFS(Tracking!I:I,A3,Tracking!D:D,C3,Tracking!C:C,"5v5",Tracking!L:L,"nsc")+COUNTIFS(Tracking!I:I,A3,Tracking!D:D,C3,Tracking!C:C,"5v5",Tracking!L:L,"nsr") | U3: =COUNTIFS(Tracking!G:G,A3,Tracking!D:D,C3,Tracking!C:C,"5v5",Tracking!J:J,"dl")+COUNTIFS(Tracking!G:G,A3,Tracking!D:D,C3,Tracking!C:C,"5v5",Tracking!J:J,"dc")+COUNTIFS(Tracking!G:G,A3,Tracking!D:D,C3,Tracking!C:C,"5v5",Tracking!J:J,"dr")+COUNTIFS(Tracking!G:G,A3,Tracking!D:D,C3,Tracking!C:C,"5v5",Tracking!J:J,"dsl")+COUNTIFS(Tracking!G:G,A3,Tracking!D:D,C3,Tracking!C:C,"5v5",Tracking!J:J,"dsc")+COUNTIFS(Tracking!G:G,A3,Tracking!D:D,C3,Tracking!C:C,"5v5",Tracking!J:J,"dsr")+COUNTIFS(Tracking!H:H,A3,Tracking!D:D,C3,Tracking!C:C,"5v5",Tracking!K:K,"dl")+COUNTIFS(Tracking!H:H,A3,Tracking!D:D,C3,Tracking!C:C,"5v5",Tracking!K:K,"dc")+COUNTIFS(Tracking!H:H,A3,Tracking!D:D,C3,Tracking!C:C,"5v5",Tracking!K:K,"dr")+COUNTIFS(Tracking!H:H,A3,Tracking!D:D,C3,Tracking!C:C,"5v5",Tracking!K:K,"dsl")+COUNTIFS(Tracking!H:H,A3,Tracking!D:D,C3,Tracking!C:C,"5v5",Tracking!K:K,"dsc")+COUNTIFS(Tracking!H:H,A3,Tracking!D:D,C3,Tracking!C:C,"5v5",Tracking!K:K,"dsr")+COUNTIFS(Tracking!I:I,A3,Tracking!D:D,C3,Tracking!C:C,"5v5",Tracking!L:L,"dl")+COUNTIFS(Tracking!I:I,A3,Tracking!D:D,C3,Tracking!C:C,"5v5",Tracking!L:L,"dc")+COUNTIFS(Tracking!I:I,A3,Tracking!D:D,C3,Tracking!C:C,"5v5",Tracking!L:L,"dr")+COUNTIFS(Tracking!I:I,A3,Tracking!D:D,C3,Tracking!C:C,"5v5",Tracking!L:L,"dsl")+COUNTIFS(Tracking!I:I,A3,Tracking!D:D,C3,Tracking!C:C,"5v5",Tracking!L:L,"dsc")+COUNTIFS(Tracking!I:I,A3,Tracking!D:D,C3,Tracking!C:C,"5v5",Tracking!L:L,"dsr") | V3: =COUNTIFS(Tracking!E:E,A3,Tracking!D:D,C3,Tracking!C:C,"5v5",Tracking!P:P,"r") | W3: =COUNTIFS(Tracking!G:G,A3,Tracking!D:D,C3,Tracking!C:C,"5v5",Tracking!P:P,"r")+COUNTIFS(Tracking!H:H,A3,Tracking!D:D,C3,Tracking!C:C,"5v5",Tracking!P:P,"r")+COUNTIFS(Tracking!I:I,A3,Tracking!D:D,C3,Tracking!C:C,"5v5",Tracking!P:P,"r") | X3: =COUNTIFS(Tracking!E:E,A3,Tracking!D:D,C3,Tracking!C:C,"5v5",Tracking!P:P,"f") | Y3: =COUNTIFS(Tracking!G:G,A3,Tracking!D:D,C3,Tracking!C:C,"5v5",Tracking!P:P,"f")+COUNTIFS(Tracking!H:H,A3,Tracking!D:D,C3,Tracking!C:C,"5v5",Tracking!P:P,"f")+COUNTIFS(Tracking!I:I,A3,Tracking!D:D,C3,Tracking!C:C,"5v5",Tracking!P:P,"f") | Z3: =COUNTIFS(Tracking!E:E,A3,Tracking!D:D,C3,Tracking!C:C,"5v5",Tracking!P:P,"c") | AA3: =COUNTIFS(Tracking!G:G,A3,Tracking!D:D,C3,Tracking!C:C,"5v5",Tracking!P:P,"c")+COUNTIFS(Tracking!H:H,A3,Tracking!D:D,C3,Tracking!C:C,"5v5",Tracking!P:P,"f")+COUNTIFS(Tracking!I:I,A3,Tracking!D:D,C3,Tracking!C:C,"5v5",Tracking!P:P,"f") | AB3: =COUNTIFS(Tracking!E:E,A3,Tracking!D:D,C3,Tracking!C:C,"5v5",Tracking!J:J,"orrl")+COUNTIFS(Tracking!E:E,A3,Tracking!D:D,C3,Tracking!C:C,"5v5",Tracking!J:J,"orrc")+COUNTIFS(Tracking!E:E,A3,Tracking!D:D,C3,Tracking!C:C,"5v5",Tracking!J:J,"orrr")+COUNTIFS(Tracking!E:E,A3,Tracking!D:D,C3,Tracking!C:C,"5v5",Tracking!J:J,"oell")+COUNTIFS(Tracking!E:E,A3,Tracking!D:D,C3,Tracking!C:C,"5v5",Tracking!J:J,"oelc")+COUNTIFS(Tracking!E:E,A3,Tracking!D:D,C3,Tracking!C:C,"5v5",Tracking!J:J,"oelr") | AC3: =COUNTIFS(Tracking!Z:Z,A3&C3,Tracking!C:C,"5v5")-AE3 | AD3: =COUNTIFS(Tracking!Z:Z,A3&C3,Tracking!C:C,"5v5",Tracking!Y:Y,"C") | AE3: =COUNTIFS(Tracking!Z:Z,A3&C3,Tracking!C:C,"5v5",Tracking!Y:Y,"F") | AF3: =COUNTIFS(Tracking!Z:Z,A3&C3,Tracking!C:C,"5v5",Tracking!Y:Y,"C",Tracking!AB:AB,"Y") | AG3: =COUNTIFS(Tracking!AD:AD,A3&C3,Tracking!C:C,"5v5") | AH3: =COUNTIFS(Tracking!Z:Z,A3&C3,Tracking!C:C,"5v5",Tracking!Y:Y,"C",Tracking!AE:AE,"Y") | AI3: =COUNTIFS(Tracking!Z:Z,A3&C3,Tracking!C:C,"5v5",Tracking!Y:Y,"D",Tracking!AE:AE,"Y") | AJ3: =COUNTIFS(Tracking!AH:AH,A3&C3) | AK3: =COUNTIFS(Tracking!AI:AI,A3&C3,Tracking!C:C,"5v5")+AL3 | AL3: =COUNTIFS(Tracking!AF:AF,A3&C3,Tracking!C:C,"5v5")-AT3 | AM3: =COUNTIFS(Tracking!AF:AF,A3&C3,Tracking!C:C,"5v5",Tracking!AG:AG,"CLE")+COUNTIFS(Tracking!AF:AF,A3&C3,Tracking!C:C,"5v5",Tracking!AG:AG,"CEX")+COUNTIFS(Tracking!AF:AF,A3&C3,Tracking!C:C,"5v5",Tracking!AG:AG,"PEX")+COUNTIFS(Tracking!AI:AI,A3&C3,Tracking!C:C,"5v5",Tracking!AJ:AJ,"CLE")+COUNTIFS(Tracking!AI:AI,A3&C3,Tracking!C:C,"5v5",Tracking!AJ:AJ,"CEX")+COUNTIFS(Tracking!AI:AI,A3&C3,Tracking!C:C,"5v5",Tracking!AJ:AJ,"PEX") | AN3: =COUNTIFS(Tracking!AF:AF,A3&C3,Tracking!C:C,"5v5",Tracking!AG:AG,"CEX")+COUNTIFS(Tracking!AF:AF,A3&C3,Tracking!C:C,"5v5",Tracking!AG:AG,"PEX")+COUNTIFS(Tracking!AI:AI,A3&C3,Tracking!C:C,"5v5",Tracking!AJ:AJ,"CEX")+COUNTIFS(Tracking!AI:AI,A3&C3,Tracking!C:C,"5v5",Tracking!AJ:AJ,"PEX") | AO3: =COUNTIFS(Tracking!AF:AF,A3&C3,Tracking!C:C,"5v5",Tracking!AG:AG,"CEX")+COUNTIFS(Tracking!AI:AI,A3&C3,Tracking!C:C,"5v5",Tracking!AJ:AJ,"CEX") | AP3: =COUNTIFS(Tracking!AF:AF,A3&C3,Tracking!C:C,"5v5",Tracking!AG:AG,"PEX") | AQ3: =COUNTIFS(Tracking!AF:AF,A3&C3,Tracking!C:C,"5v5",Tracking!AG:AG,"CLE")+COUNTIFS(Tracking!AI:AI,A3&C3,Tracking!C:C,"5v5",Tracking!AJ:AJ,"CLE") | AR3: =COUNTIFS(Tracking!AF:AF,A3&C3,Tracking!C:C,"5v5",Tracking!AG:AG,"MEX") | AS3: =COUNTIFS(Tracking!AF:AF,A3&C3,Tracking!C:C,"5v5",Tracking!AJ:AJ,"CEX")+COUNTIFS(Tracking!AF:AF,A3&C3,Tracking!C:C,"5v5",Tracking!AJ:AJ,"PEX")+COUNTIFS(Tracking!AF:AF,A3&C3,Tracking!C:C,"5v5",Tracking!AJ:AJ,"CLE")+COUNTIFS(Tracking!AF:AF,A3&C3,Tracking!C:C,"5v5",Tracking!AG:AG,"CEX")+COUNTIFS(Tracking!AF:AF,A3&C3,Tracking!C:C,"5v5",Tracking!AG:AG,"PEX") | AT3: =COUNTIFS(Tracking!AF:AF,A3&C3,Tracking!C:C,"5v5",Tracking!AG:AG,"BOT")+COUNTIFS(Tracking!AF:AF,A3&C3,Tracking!C:C,"5v5",Tracking!AG:AG,"FEX") | AU3: =COUNTIFS(Tracking!AF:AF,A3&C3,Tracking!C:C,"5v5",Tracking!AG:AG,"EXC") | AV3: =COUNTIFS(Tracking!AF:AF,A3&C3,Tracking!C:C,"5v5",Tracking!AG:AG,"FEX")+COUNTIFS(Tracking!AI:AI,A3&C3,Tracking!C:C,"5v5",Tracking!AJ:AJ,"FEX") | AW3: =COUNTIFS(Tracking!AF:AF,A3&C3,Tracking!C:C,"5v5",Tracking!AG:AG,"CLE")+COUNTIFS(Tracking!AF:AF,A3&C3,Tracking!C:C,"5v5",Tracking!AG:AG,"CEX")+COUNTIFS(Tracking!AF:AF,A3&C3,Tracking!C:C,"5v5",Tracking!AG:AG,"PEX") | AX3: =COUNTIFS(Tracking!AI:AI,A3&C3,Tracking!C:C,"5v5",Tracking!AJ:AJ,"CLE")+COUNTIFS(Tracking!AI:AI,A3&C3,Tracking!C:C,"5v5",Tracking!AJ:AJ,"CEX")+COUNTIFS(Tracking!AI:AI,A3&C3,Tracking!C:C,"5v5",Tracking!AJ:AJ,"PEX") | AY3: =COUNTIFS(Tracking!AA:AA,A3&C3,Tracking!C:C,"5v5") | AZ3: =COUNTIFS(Tracking!AA:AA,A3&C3,Tracking!C:C,"5v5",Tracking!Y:Y,"C") | BA3: =COUNTIFS(Tracking!AA:AA,A3&C3,Tracking!C:C,"5v5",Tracking!Y:Y,"F") | BB3: =COUNTIFS(Tracking!AA:AA,A3&C3,Tracking!C:C,"5v5",Tracking!AB:AB,"Y") | BC3: =COUNTIFS(Tracking!AA:AA,A3&C3,Tracking!C:C,"5v5",Tracking!Y:Y,"C",Tracking!AE:AE,"Y") | BD3: =COUNTIFS(Tracking!AA:AA,A3&C3,Tracking!C:C,"5v5",Tracking!Y:Y,"D",Tracking!AE:AE,"Y") | BE3: =COUNTIFS(Tracking!Z:Z,A3&C3,Tracking!C:C,"5v4") | BF3: =COUNTIFS(Tracking!Z:Z,A3&C3,Tracking!C:C,"5v4",Tracking!Y:Y,"C") | BG3: =COUNTIFS(Tracking!Z:Z,A3&C3,Tracking!C:C,"5v4",Tracking!AB:AB,"Y") | BH3: =COUNTIFS(Tracking!Z:Z,A3&C3,Tracking!C:C,"4v5") | BI3: =COUNTIFS(Tracking!AA:AA,A3&C3,Tracking!C:C,"5v4",Tracking!Y:Y,"D")+COUNTIFS(Tracking!AA:AA,A3&C3,Tracking!C:C,"5v4",Tracking!Y:Y,"F") | BJ3: =COUNTIFS(Tracking!E:E,A3,Tracking!D:D,C3,Tracking!C:C,"5v4") | BK3: =COUNTIFS(Tracking!G:G,A3,Tracking!D:D,C3,Tracking!C:C,"5v4")+COUNTIFS(Tracking!H:H,A3,Tracking!D:D,C3,Tracking!C:C,"5v4")+COUNTIFS(Tracking!I:I,A3,Tracking!D:D,C3,Tracking!C:C,"5v4") | BL3: =COUNTIFS(Tracking!G:G,A3,Tracking!D:D,C3,Tracking!C:C,"5v4") | BM3: =COUNTIFS(Tracking!E:E,A3,Tracking!D:D,C3,Tracking!C:C,"5v4",Tracking!M:M,"Y") | BN3: =COUNTIFS(Tracking!G:G,A3,Tracking!D:D,C3,Tracking!C:C,"5v4",Tracking!M:M,"Y") | BO3: =COUNTIFS(Tracking!G:G,A3,Tracking!D:D,C3,Tracking!J:J,"orrl",Tracking!C:C,"5v4")+COUNTIFS(Tracking!G:G,A3,Tracking!D:D,C3,Tracking!J:J,"orrc",Tracking!C:C,"5v4")+COUNTIFS(Tracking!G:G,A3,Tracking!D:D,C3,Tracking!J:J,"orrr",Tracking!C:C,"5v4") | BP3: =COUNTIFS(Tracking!G:G,A3,Tracking!D:D,C3,Tracking!C:C,"5v4",Tracking!J:J,"opl")+COUNTIFS(Tracking!G:G,A3,Tracking!D:D,C3,Tracking!C:C,"5v4",Tracking!J:J,"opc")+COUNTIFS(Tracking!G:G,A3,Tracking!D:D,C3,Tracking!C:C,"5v4",Tracking!J:J,"opr")+COUNTIFS(Tracking!G:G,A3,Tracking!D:D,C3,Tracking!C:C,"5v4",Tracking!J:J,"oelpl")+COUNTIFS(Tracking!G:G,A3,Tracking!D:D,C3,Tracking!C:C,"5v4",Tracking!J:J,"oelpc")+COUNTIFS(Tracking!G:G,A3,Tracking!D:D,C3,Tracking!C:C,"5v4",Tracking!J:J,"oelpr") | BQ3: =COUNTIFS(Tracking!G:G,A3,Tracking!D:D,C3,Tracking!C:C,"5v4",Tracking!J:J,"oell")+COUNTIFS(Tracking!G:G,A3,Tracking!D:D,C3,Tracking!C:C,"5v4",Tracking!J:J,"oelc")+COUNTIFS(Tracking!G:G,A3,Tracking!D:D,C3,Tracking!C:C,"5v4",Tracking!J:J,"oelr") | BR3: =COUNTIFS(Tracking!E:E,A3,Tracking!D:D,C3,Tracking!C:C,"5v5",Tracking!F:F,"o") | BS3: =COUNTIFS(Tracking!E:E,A3,Tracking!D:D,C3,Tracking!C:C,"5v5",Tracking!F:F,"r") | BT3: =COUNTIFS(Tracking!E:E,A3,Tracking!D:D,C3,Tracking!C:C,"5v5",Tracking!F:F,"t") | BU3: =COUNTIFS(Tracking!G:G,A3,Tracking!D:D,C3,Tracking!C:C,"5v5",Tracking!F:F,"o") | BV3: =COUNTIFS(Tracking!E:E,A2,Tracking!D:D,C3,Tracking!C:C,"5v5",Tracking!F:F,"r") | BW3: =COUNTIFS(Tracking!G:G,A3,Tracking!D:D,C3,Tracking!C:C,"5v5",Tracking!F:F,"T") | BX3: =COUNTIFS(Tracking!E:E,A3,Tracking!D:D,C3,Tracking!C:C,"5v5",Tracking!Q:Q,"OZ") | BY3: =COUNTIFS(Tracking!E:E,A3,Tracking!D:D,C3,Tracking!C:C,"5v5",Tracking!Q:Q,"nZ") | BZ3: =COUNTIFS(Tracking!E:E,A3,Tracking!D:D,C3,Tracking!C:C,"5v5",Tracking!Q:Q,"dZ") | CA3: =COUNTIFS(Tracking!G:G,A3,Tracking!D:D,C3,Tracking!C:C,"5v5",Tracking!Q:Q,"OZ")+COUNTIFS(Tracking!H:H,A3,Tracking!D:D,C3,Tracking!C:C,"5v5",Tracking!Q:Q,"OZ")+COUNTIFS(Tracking!I:I,A3,Tracking!D:D,C3,Tracking!C:C,"5v5",Tracking!Q:Q,"OZ") | CB3: =COUNTIFS(Tracking!G:G,A3,Tracking!D:D,C3,Tracking!C:C,"5v5",Tracking!Q:Q,"nZ")+COUNTIFS(Tracking!H:H,A3,Tracking!D:D,C3,Tracking!C:C,"5v5",Tracking!Q:Q,"nZ")+COUNTIFS(Tracking!I:I,A3,Tracking!D:D,C3,Tracking!C:C,"5v5",Tracking!Q:Q,"nZ") | CC3: =COUNTIFS(Tracking!G:G,A3,Tracking!D:D,C3,Tracking!C:C,"5v5",Tracking!Q:Q,"dZ")+COUNTIFS(Tracking!H:H,A3,Tracking!D:D,C3,Tracking!C:C,"5v5",Tracking!Q:Q,"dZ")+COUNTIFS(Tracking!I:I,A3,Tracking!D:D,C3,Tracking!C:C,"5v5",Tracking!Q:Q,"dZ") | CD3: =COUNTIFS(Tracking!E:E,A3,Tracking!D:D,C3,Tracking!C:C,"5v5",Tracking!R:R,"dz exit") | CE3: =COUNTIFS(Tracking!E:E,A3,Tracking!D:D,C3,Tracking!C:C,"5v5",Tracking!R:R,"dz counter") | CF3: =COUNTIFS(Tracking!E:E,A3,Tracking!D:D,C3,Tracking!C:C,"5v5",Tracking!R:R,"nz turnover") | CG3: =COUNTIFS(Tracking!E:E,A3,Tracking!D:D,C3,Tracking!C:C,"5v5",Tracking!R:R,"nz regroup") | CH3: =COUNTIFS(Tracking!E:E,A3,Tracking!D:D,C3,Tracking!C:C,"5v5",Tracking!R:R,"nz reload") | CI3: =COUNTIFS(Tracking!E:E,A3,Tracking!D:D,C3,Tracking!C:C,"5v5",Tracking!R:R,"controlled breakout") | CJ3: =CK3+CL3+CM3+CN3+CO3+CP3 | CK3: =(0.075*H3)+(0.07*L3)+(0.055*M3)+(0.055*N3)+(0.095*J3)+(0.09*O3)+(0.05*P3)+(0.05*R3)+(0.05*S3)+(0.05*AB3) | CL3: =(0.045*AD3)-(0.045*AE3)+(0.055*AH3)+(0.035*AI3) | CM3: =(0.025*(AY3-AZ3))+(0.035*BA3)-(0.015*BB3)-(0.015*BC3)+(0.015*(AY3-(BD3+BC3))) | CN3: =(0.035*AN3)+(0.025*AS3)-(0.035*AT3)-(0.035*AV3) | CO3: =(0.015*AJ3)+(0.045*AG3) | CP3: =(0.055*BM3)+(0.055*BN3)+(0.035*BO3)+(0.035*BQ3)+(0.055*BH3)+(0.035*BI3)+(0.035*BG3) | CQ3: =CK3+CL3+CM3+CN3+CO3
A4: 23 | B4: Esa Lindell | C4: DAL | D4: D | E4: 16.9 | F4: 2025-26 | G4: 3/6/2026 DAL vs. COL | H4: =COUNTIFS(Tracking!E:E,A4,Tracking!D:D,C4,Tracking!C:C,"5v5") | I4: =COUNTIFS(Tracking!E:E,A4,Tracking!D:D,C4,Tracking!N:N,"y",Tracking!C:C,"5v5") | J4: =COUNTIFS(Tracking!E:E,A4,Tracking!D:D,C4,Tracking!M:M,"y",Tracking!C:C,"5v5") | K4: =L4+M4+N4 | L4: =COUNTIFS(Tracking!G:G,A4,Tracking!D:D,C4,Tracking!C:C,"5v5") | M4: =COUNTIFS(Tracking!H:H,A4,Tracking!D:D,C4,Tracking!C:C,"5v5") | N4: =COUNTIFS(Tracking!I:I,A4,Tracking!D:D,C4,Tracking!C:C,"5v5") | O4: =COUNTIFS(Tracking!G:G,A4,Tracking!D:D,C4,Tracking!C:C,"5v5",Tracking!M:M,"y") | P4: =COUNTIFS(Tracking!G:G,A4,Tracking!D:D,C4,Tracking!C:C,"5v5",Tracking!J:J,"orrl")+COUNTIFS(Tracking!G:G,A4,Tracking!D:D,C4,Tracking!C:C,"5v5",Tracking!J:J,"orrc")+COUNTIFS(Tracking!G:G,A4,Tracking!D:D,C4,Tracking!C:C,"5v5",Tracking!J:J,"orrr")+COUNTIFS(Tracking!G:G,A4,Tracking!D:D,C4,Tracking!C:C,"5v5",Tracking!J:J,"oelrrl")+COUNTIFS(Tracking!G:G,A4,Tracking!D:D,C4,Tracking!C:C,"5v5",Tracking!J:J,"oelrrc")+COUNTIFS(Tracking!G:G,A4,Tracking!D:D,C4,Tracking!C:C,"5v5",Tracking!J:J,"oelrrr") | Q4: =COUNTIFS(Tracking!G:G,A4,Tracking!D:D,C4,Tracking!C:C,"5v5",Tracking!J:J,"opl")+COUNTIFS(Tracking!G:G,A4,Tracking!D:D,C4,Tracking!C:C,"5v5",Tracking!J:J,"opc")+COUNTIFS(Tracking!G:G,A4,Tracking!D:D,C4,Tracking!C:C,"5v5",Tracking!J:J,"opr")+COUNTIFS(Tracking!G:G,A4,Tracking!D:D,C4,Tracking!C:C,"5v5",Tracking!J:J,"oelpl")+COUNTIFS(Tracking!G:G,A4,Tracking!D:D,C4,Tracking!C:C,"5v5",Tracking!J:J,"oelpc")+COUNTIFS(Tracking!G:G,A4,Tracking!D:D,C4,Tracking!C:C,"5v5",Tracking!J:J,"oelpr") | R4: =COUNTIFS(Tracking!G:G,A4,Tracking!D:D,C4,Tracking!C:C,"5v5",Tracking!J:J,"oell")+COUNTIFS(Tracking!G:G,A4,Tracking!D:D,C4,Tracking!C:C,"5v5",Tracking!J:J,"oelc")+COUNTIFS(Tracking!G:G,A4,Tracking!D:D,C4,Tracking!C:C,"5v5",Tracking!J:J,"oelr") | S4: =COUNTIFS(Tracking!G:G,A4,Tracking!D:D,C4,Tracking!C:C,"5v5",Tracking!J:J,"oc")+COUNTIFS(Tracking!G:G,A4,Tracking!D:D,C4,Tracking!C:C,"5v5",Tracking!J:J,"orrc")+COUNTIFS(Tracking!G:G,A4,Tracking!D:D,C4,Tracking!C:C,"5v5",Tracking!J:J,"oelc") | T4: =COUNTIFS(Tracking!G:G,A4,Tracking!D:D,C4,Tracking!C:C,"5v5",Tracking!J:J,"nl")+COUNTIFS(Tracking!G:G,A4,Tracking!D:D,C4,Tracking!C:C,"5v5",Tracking!J:J,"nc")+COUNTIFS(Tracking!G:G,A4,Tracking!D:D,C4,Tracking!C:C,"5v5",Tracking!J:J,"nr")+COUNTIFS(Tracking!G:G,A4,Tracking!D:D,C4,Tracking!C:C,"5v5",Tracking!J:J,"nsl")+COUNTIFS(Tracking!G:G,A4,Tracking!D:D,C4,Tracking!C:C,"5v5",Tracking!J:J,"nsc")+COUNTIFS(Tracking!G:G,A4,Tracking!D:D,C4,Tracking!C:C,"5v5",Tracking!J:J,"nsr")+COUNTIFS(Tracking!H:H,A4,Tracking!D:D,C4,Tracking!C:C,"5v5",Tracking!K:K,"nl")+COUNTIFS(Tracking!H:H,A4,Tracking!D:D,C4,Tracking!C:C,"5v5",Tracking!K:K,"nc")+COUNTIFS(Tracking!H:H,A4,Tracking!D:D,C4,Tracking!C:C,"5v5",Tracking!K:K,"nr")+COUNTIFS(Tracking!H:H,A4,Tracking!D:D,C4,Tracking!C:C,"5v5",Tracking!K:K,"nsl")+COUNTIFS(Tracking!H:H,A4,Tracking!D:D,C4,Tracking!C:C,"5v5",Tracking!K:K,"nsc")+COUNTIFS(Tracking!H:H,A4,Tracking!D:D,C4,Tracking!C:C,"5v5",Tracking!K:K,"nsr")+COUNTIFS(Tracking!I:I,A4,Tracking!D:D,C4,Tracking!C:C,"5v5",Tracking!L:L,"nl")+COUNTIFS(Tracking!I:I,A4,Tracking!D:D,C4,Tracking!C:C,"5v5",Tracking!L:L,"nc")+COUNTIFS(Tracking!I:I,A4,Tracking!D:D,C4,Tracking!C:C,"5v5",Tracking!L:L,"nr")+COUNTIFS(Tracking!I:I,A4,Tracking!D:D,C4,Tracking!C:C,"5v5",Tracking!L:L,"nsl")+COUNTIFS(Tracking!I:I,A4,Tracking!D:D,C4,Tracking!C:C,"5v5",Tracking!L:L,"nsc")+COUNTIFS(Tracking!I:I,A4,Tracking!D:D,C4,Tracking!C:C,"5v5",Tracking!L:L,"nsr") | U4: =COUNTIFS(Tracking!G:G,A4,Tracking!D:D,C4,Tracking!C:C,"5v5",Tracking!J:J,"dl")+COUNTIFS(Tracking!G:G,A4,Tracking!D:D,C4,Tracking!C:C,"5v5",Tracking!J:J,"dc")+COUNTIFS(Tracking!G:G,A4,Tracking!D:D,C4,Tracking!C:C,"5v5",Tracking!J:J,"dr")+COUNTIFS(Tracking!G:G,A4,Tracking!D:D,C4,Tracking!C:C,"5v5",Tracking!J:J,"dsl")+COUNTIFS(Tracking!G:G,A4,Tracking!D:D,C4,Tracking!C:C,"5v5",Tracking!J:J,"dsc")+COUNTIFS(Tracking!G:G,A4,Tracking!D:D,C4,Tracking!C:C,"5v5",Tracking!J:J,"dsr")+COUNTIFS(Tracking!H:H,A4,Tracking!D:D,C4,Tracking!C:C,"5v5",Tracking!K:K,"dl")+COUNTIFS(Tracking!H:H,A4,Tracking!D:D,C4,Tracking!C:C,"5v5",Tracking!K:K,"dc")+COUNTIFS(Tracking!H:H,A4,Tracking!D:D,C4,Tracking!C:C,"5v5",Tracking!K:K,"dr")+COUNTIFS(Tracking!H:H,A4,Tracking!D:D,C4,Tracking!C:C,"5v5",Tracking!K:K,"dsl")+COUNTIFS(Tracking!H:H,A4,Tracking!D:D,C4,Tracking!C:C,"5v5",Tracking!K:K,"dsc")+COUNTIFS(Tracking!H:H,A4,Tracking!D:D,C4,Tracking!C:C,"5v5",Tracking!K:K,"dsr")+COUNTIFS(Tracking!I:I,A4,Tracking!D:D,C4,Tracking!C:C,"5v5",Tracking!L:L,"dl")+COUNTIFS(Tracking!I:I,A4,Tracking!D:D,C4,Tracking!C:C,"5v5",Tracking!L:L,"dc")+COUNTIFS(Tracking!I:I,A4,Tracking!D:D,C4,Tracking!C:C,"5v5",Tracking!L:L,"dr")+COUNTIFS(Tracking!I:I,A4,Tracking!D:D,C4,Tracking!C:C,"5v5",Tracking!L:L,"dsl")+COUNTIFS(Tracking!I:I,A4,Tracking!D:D,C4,Tracking!C:C,"5v5",Tracking!L:L,"dsc")+COUNTIFS(Tracking!I:I,A4,Tracking!D:D,C4,Tracking!C:C,"5v5",Tracking!L:L,"dsr") | V4: =COUNTIFS(Tracking!E:E,A4,Tracking!D:D,C4,Tracking!C:C,"5v5",Tracking!P:P,"r") | W4: =COUNTIFS(Tracking!G:G,A4,Tracking!D:D,C4,Tracking!C:C,"5v5",Tracking!P:P,"r")+COUNTIFS(Tracking!H:H,A4,Tracking!D:D,C4,Tracking!C:C,"5v5",Tracking!P:P,"r")+COUNTIFS(Tracking!I:I,A4,Tracking!D:D,C4,Tracking!C:C,"5v5",Tracking!P:P,"r") | X4: =COUNTIFS(Tracking!E:E,A4,Tracking!D:D,C4,Tracking!C:C,"5v5",Tracking!P:P,"f") | Y4: =COUNTIFS(Tracking!G:G,A4,Tracking!D:D,C4,Tracking!C:C,"5v5",Tracking!P:P,"f")+COUNTIFS(Tracking!H:H,A4,Tracking!D:D,C4,Tracking!C:C,"5v5",Tracking!P:P,"f")+COUNTIFS(Tracking!I:I,A4,Tracking!D:D,C4,Tracking!C:C,"5v5",Tracking!P:P,"f") | Z4: =COUNTIFS(Tracking!E:E,A4,Tracking!D:D,C4,Tracking!C:C,"5v5",Tracking!P:P,"c") | AA4: =COUNTIFS(Tracking!G:G,A4,Tracking!D:D,C4,Tracking!C:C,"5v5",Tracking!P:P,"c")+COUNTIFS(Tracking!H:H,A4,Tracking!D:D,C4,Tracking!C:C,"5v5",Tracking!P:P,"f")+COUNTIFS(Tracking!I:I,A4,Tracking!D:D,C4,Tracking!C:C,"5v5",Tracking!P:P,"f") | AB4: =COUNTIFS(Tracking!E:E,A4,Tracking!D:D,C4,Tracking!C:C,"5v5",Tracking!J:J,"orrl")+COUNTIFS(Tracking!E:E,A4,Tracking!D:D,C4,Tracking!C:C,"5v5",Tracking!J:J,"orrc")+COUNTIFS(Tracking!E:E,A4,Tracking!D:D,C4,Tracking!C:C,"5v5",Tracking!J:J,"orrr")+COUNTIFS(Tracking!E:E,A4,Tracking!D:D,C4,Tracking!C:C,"5v5",Tracking!J:J,"oell")+COUNTIFS(Tracking!E:E,A4,Tracking!D:D,C4,Tracking!C:C,"5v5",Tracking!J:J,"oelc")+COUNTIFS(Tracking!E:E,A4,Tracking!D:D,C4,Tracking!C:C,"5v5",Tracking!J:J,"oelr") | AC4: =COUNTIFS(Tracking!Z:Z,A4&C4,Tracking!C:C,"5v5")-AE4 | AD4: =COUNTIFS(Tracking!Z:Z,A4&C4,Tracking!C:C,"5v5",Tracking!Y:Y,"C") | AE4: =COUNTIFS(Tracking!Z:Z,A4&C4,Tracking!C:C,"5v5",Tracking!Y:Y,"F") | AF4: =COUNTIFS(Tracking!Z:Z,A4&C4,Tracking!C:C,"5v5",Tracking!Y:Y,"C",Tracking!AB:AB,"Y") | AG4: =COUNTIFS(Tracking!AD:AD,A4&C4,Tracking!C:C,"5v5") | AH4: =COUNTIFS(Tracking!Z:Z,A4&C4,Tracking!C:C,"5v5",Tracking!Y:Y,"C",Tracking!AE:AE,"Y") | AI4: =COUNTIFS(Tracking!Z:Z,A4&C4,Tracking!C:C,"5v5",Tracking!Y:Y,"D",Tracking!AE:AE,"Y") | AJ4: =COUNTIFS(Tracking!AH:AH,A4&C4) | AK4: =COUNTIFS(Tracking!AI:AI,A4&C4,Tracking!C:C,"5v5")+AL4 | AL4: =COUNTIFS(Tracking!AF:AF,A4&C4,Tracking!C:C,"5v5")-AT4 | AM4: =COUNTIFS(Tracking!AF:AF,A4&C4,Tracking!C:C,"5v5",Tracking!AG:AG,"CLE")+COUNTIFS(Tracking!AF:AF,A4&C4,Tracking!C:C,"5v5",Tracking!AG:AG,"CEX")+COUNTIFS(Tracking!AF:AF,A4&C4,Tracking!C:C,"5v5",Tracking!AG:AG,"PEX")+COUNTIFS(Tracking!AI:AI,A4&C4,Tracking!C:C,"5v5",Tracking!AJ:AJ,"CLE")+COUNTIFS(Tracking!AI:AI,A4&C4,Tracking!C:C,"5v5",Tracking!AJ:AJ,"CEX")+COUNTIFS(Tracking!AI:AI,A4&C4,Tracking!C:C,"5v5",Tracking!AJ:AJ,"PEX") | AN4: =COUNTIFS(Tracking!AF:AF,A4&C4,Tracking!C:C,"5v5",Tracking!AG:AG,"CEX")+COUNTIFS(Tracking!AF:AF,A4&C4,Tracking!C:C,"5v5",Tracking!AG:AG,"PEX")+COUNTIFS(Tracking!AI:AI,A4&C4,Tracking!C:C,"5v5",Tracking!AJ:AJ,"CEX")+COUNTIFS(Tracking!AI:AI,A4&C4,Tracking!C:C,"5v5",Tracking!AJ:AJ,"PEX") | AO4: =COUNTIFS(Tracking!AF:AF,A4&C4,Tracking!C:C,"5v5",Tracking!AG:AG,"CEX")+COUNTIFS(Tracking!AI:AI,A4&C4,Tracking!C:C,"5v5",Tracking!AJ:AJ,"CEX") | AP4: =COUNTIFS(Tracking!AF:AF,A4&C4,Tracking!C:C,"5v5",Tracking!AG:AG,"PEX") | AQ4: =COUNTIFS(Tracking!AF:AF,A4&C4,Tracking!C:C,"5v5",Tracking!AG:AG,"CLE")+COUNTIFS(Tracking!AI:AI,A4&C4,Tracking!C:C,"5v5",Tracking!AJ:AJ,"CLE") | AR4: =COUNTIFS(Tracking!AF:AF,A4&C4,Tracking!C:C,"5v5",Tracking!AG:AG,"MEX") | AS4: =COUNTIFS(Tracking!AF:AF,A4&C4,Tracking!C:C,"5v5",Tracking!AJ:AJ,"CEX")+COUNTIFS(Tracking!AF:AF,A4&C4,Tracking!C:C,"5v5",Tracking!AJ:AJ,"PEX")+COUNTIFS(Tracking!AF:AF,A4&C4,Tracking!C:C,"5v5",Tracking!AJ:AJ,"CLE")+COUNTIFS(Tracking!AF:AF,A4&C4,Tracking!C:C,"5v5",Tracking!AG:AG,"CEX")+COUNTIFS(Tracking!AF:AF,A4&C4,Tracking!C:C,"5v5",Tracking!AG:AG,"PEX") | AT4: =COUNTIFS(Tracking!AF:AF,A4&C4,Tracking!C:C,"5v5",Tracking!AG:AG,"BOT")+COUNTIFS(Tracking!AF:AF,A4&C4,Tracking!C:C,"5v5",Tracking!AG:AG,"FEX") | AU4: =COUNTIFS(Tracking!AF:AF,A4&C4,Tracking!C:C,"5v5",Tracking!AG:AG,"EXC") | AV4: =COUNTIFS(Tracking!AF:AF,A4&C4,Tracking!C:C,"5v5",Tracking!AG:AG,"FEX")+COUNTIFS(Tracking!AI:AI,A4&C4,Tracking!C:C,"5v5",Tracking!AJ:AJ,"FEX") | AW4: =COUNTIFS(Tracking!AF:AF,A4&C4,Tracking!C:C,"5v5",Tracking!AG:AG,"CLE")+COUNTIFS(Tracking!AF:AF,A4&C4,Tracking!C:C,"5v5",Tracking!AG:AG,"CEX")+COUNTIFS(Tracking!AF:AF,A4&C4,Tracking!C:C,"5v5",Tracking!AG:AG,"PEX") | AX4: =COUNTIFS(Tracking!AI:AI,A4&C4,Tracking!C:C,"5v5",Tracking!AJ:AJ,"CLE")+COUNTIFS(Tracking!AI:AI,A4&C4,Tracking!C:C,"5v5",Tracking!AJ:AJ,"CEX")+COUNTIFS(Tracking!AI:AI,A4&C4,Tracking!C:C,"5v5",Tracking!AJ:AJ,"PEX") | AY4: =COUNTIFS(Tracking!AA:AA,A4&C4,Tracking!C:C,"5v5") | AZ4: =COUNTIFS(Tracking!AA:AA,A4&C4,Tracking!C:C,"5v5",Tracking!Y:Y,"C") | BA4: =COUNTIFS(Tracking!AA:AA,A4&C4,Tracking!C:C,"5v5",Tracking!Y:Y,"F") | BB4: =COUNTIFS(Tracking!AA:AA,A4&C4,Tracking!C:C,"5v5",Tracking!AB:AB,"Y") | BC4: =COUNTIFS(Tracking!AA:AA,A4&C4,Tracking!C:C,"5v5",Tracking!Y:Y,"C",Tracking!AE:AE,"Y") | BD4: =COUNTIFS(Tracking!AA:AA,A4&C4,Tracking!C:C,"5v5",Tracking!Y:Y,"D",Tracking!AE:AE,"Y") | BE4: =COUNTIFS(Tracking!Z:Z,A4&C4,Tracking!C:C,"5v4") | BF4: =COUNTIFS(Tracking!Z:Z,A4&C4,Tracking!C:C,"5v4",Tracking!Y:Y,"C") | BG4: =COUNTIFS(Tracking!Z:Z,A4&C4,Tracking!C:C,"5v4",Tracking!AB:AB,"Y") | BH4: =COUNTIFS(Tracking!Z:Z,A4&C4,Tracking!C:C,"4v5") | BI4: =COUNTIFS(Tracking!AA:AA,A4&C4,Tracking!C:C,"5v4",Tracking!Y:Y,"D")+COUNTIFS(Tracking!AA:AA,A4&C4,Tracking!C:C,"5v4",Tracking!Y:Y,"F") | BJ4: =COUNTIFS(Tracking!E:E,A4,Tracking!D:D,C4,Tracking!C:C,"5v4") | BK4: =COUNTIFS(Tracking!G:G,A4,Tracking!D:D,C4,Tracking!C:C,"5v4")+COUNTIFS(Tracking!H:H,A4,Tracking!D:D,C4,Tracking!C:C,"5v4")+COUNTIFS(Tracking!I:I,A4,Tracking!D:D,C4,Tracking!C:C,"5v4") | BL4: =COUNTIFS(Tracking!G:G,A4,Tracking!D:D,C4,Tracking!C:C,"5v4") | BM4: =COUNTIFS(Tracking!E:E,A4,Tracking!D:D,C4,Tracking!C:C,"5v4",Tracking!M:M,"Y") | BN4: =COUNTIFS(Tracking!G:G,A4,Tracking!D:D,C4,Tracking!C:C,"5v4",Tracking!M:M,"Y") | BO4: =COUNTIFS(Tracking!G:G,A4,Tracking!D:D,C4,Tracking!J:J,"orrl",Tracking!C:C,"5v4")+COUNTIFS(Tracking!G:G,A4,Tracking!D:D,C4,Tracking!J:J,"orrc",Tracking!C:C,"5v4")+COUNTIFS(Tracking!G:G,A4,Tracking!D:D,C4,Tracking!J:J,"orrr",Tracking!C:C,"5v4") | BP4: =COUNTIFS(Tracking!G:G,A4,Tracking!D:D,C4,Tracking!C:C,"5v4",Tracking!J:J,"opl")+COUNTIFS(Tracking!G:G,A4,Tracking!D:D,C4,Tracking!C:C,"5v4",Tracking!J:J,"opc")+COUNTIFS(Tracking!G:G,A4,Tracking!D:D,C4,Tracking!C:C,"5v4",Tracking!J:J,"opr")+COUNTIFS(Tracking!G:G,A4,Tracking!D:D,C4,Tracking!C:C,"5v4",Tracking!J:J,"oelpl")+COUNTIFS(Tracking!G:G,A4,Tracking!D:D,C4,Tracking!C:C,"5v4",Tracking!J:J,"oelpc")+COUNTIFS(Tracking!G:G,A4,Tracking!D:D,C4,Tracking!C:C,"5v4",Tracking!J:J,"oelpr") | BQ4: =COUNTIFS(Tracking!G:G,A4,Tracking!D:D,C4,Tracking!C:C,"5v4",Tracking!J:J,"oell")+COUNTIFS(Tracking!G:G,A4,Tracking!D:D,C4,Tracking!C:C,"5v4",Tracking!J:J,"oelc")+COUNTIFS(Tracking!G:G,A4,Tracking!D:D,C4,Tracking!C:C,"5v4",Tracking!J:J,"oelr") | BR4: =COUNTIFS(Tracking!E:E,A4,Tracking!D:D,C4,Tracking!C:C,"5v5",Tracking!F:F,"o") | BS4: =COUNTIFS(Tracking!E:E,A4,Tracking!D:D,C4,Tracking!C:C,"5v5",Tracking!F:F,"r") | BT4: =COUNTIFS(Tracking!E:E,A4,Tracking!D:D,C4,Tracking!C:C,"5v5",Tracking!F:F,"t") | BU4: =COUNTIFS(Tracking!G:G,A4,Tracking!D:D,C4,Tracking!C:C,"5v5",Tracking!F:F,"o") | BV4: =COUNTIFS(Tracking!E:E,A3,Tracking!D:D,C4,Tracking!C:C,"5v5",Tracking!F:F,"r") | BW4: =COUNTIFS(Tracking!G:G,A4,Tracking!D:D,C4,Tracking!C:C,"5v5",Tracking!F:F,"T") | BX4: =COUNTIFS(Tracking!E:E,A4,Tracking!D:D,C4,Tracking!C:C,"5v5",Tracking!Q:Q,"OZ") | BY4: =COUNTIFS(Tracking!E:E,A4,Tracking!D:D,C4,Tracking!C:C,"5v5",Tracking!Q:Q,"nZ") | BZ4: =COUNTIFS(Tracking!E:E,A4,Tracking!D:D,C4,Tracking!C:C,"5v5",Tracking!Q:Q,"dZ") | CA4: =COUNTIFS(Tracking!G:G,A4,Tracking!D:D,C4,Tracking!C:C,"5v5",Tracking!Q:Q,"OZ")+COUNTIFS(Tracking!H:H,A4,Tracking!D:D,C4,Tracking!C:C,"5v5",Tracking!Q:Q,"OZ")+COUNTIFS(Tracking!I:I,A4,Tracking!D:D,C4,Tracking!C:C,"5v5",Tracking!Q:Q,"OZ") | CB4: =COUNTIFS(Tracking!G:G,A4,Tracking!D:D,C4,Tracking!C:C,"5v5",Tracking!Q:Q,"nZ")+COUNTIFS(Tracking!H:H,A4,Tracking!D:D,C4,Tracking!C:C,"5v5",Tracking!Q:Q,"nZ")+COUNTIFS(Tracking!I:I,A4,Tracking!D:D,C4,Tracking!C:C,"5v5",Tracking!Q:Q,"nZ") | CC4: =COUNTIFS(Tracking!G:G,A4,Tracking!D:D,C4,Tracking!C:C,"5v5",Tracking!Q:Q,"dZ")+COUNTIFS(Tracking!H:H,A4,Tracking!D:D,C4,Tracking!C:C,"5v5",Tracking!Q:Q,"dZ")+COUNTIFS(Tracking!I:I,A4,Tracking!D:D,C4,Tracking!C:C,"5v5",Tracking!Q:Q,"dZ") | CD4: =COUNTIFS(Tracking!E:E,A4,Tracking!D:D,C4,Tracking!C:C,"5v5",Tracking!R:R,"dz exit") | CE4: =COUNTIFS(Tracking!E:E,A4,Tracking!D:D,C4,Tracking!C:C,"5v5",Tracking!R:R,"dz counter") | CF4: =COUNTIFS(Tracking!E:E,A4,Tracking!D:D,C4,Tracking!C:C,"5v5",Tracking!R:R,"nz turnover") | CG4: =COUNTIFS(Tracking!E:E,A4,Tracking!D:D,C4,Tracking!C:C,"5v5",Tracking!R:R,"nz regroup") | CH4: =COUNTIFS(Tracking!E:E,A4,Tracking!D:D,C4,Tracking!C:C,"5v5",Tracking!R:R,"nz reload") | CI4: =COUNTIFS(Tracking!E:E,A4,Tracking!D:D,C4,Tracking!C:C,"5v5",Tracking!R:R,"controlled breakout") | CJ4: =CK4+CL4+CM4+CN4+CO4+CP4 | CK4: =(0.075*H4)+(0.07*L4)+(0.055*M4)+(0.055*N4)+(0.095*J4)+(0.09*O4)+(0.05*P4)+(0.05*R4)+(0.05*S4)+(0.05*AB4) | CL4: =(0.045*AD4)-(0.045*AE4)+(0.055*AH4)+(0.035*AI4) | CM4: =(0.015*(AY4-AZ4))+(0.035*BA4)-(0.015*BB4)-(0.025*BC4)+(0.015*(AY4-(BD4+BC4))) | CN4: =(0.035*AN4)+(0.025*AS4)-(0.035*AT4)-(0.035*AV4) | CO4: =(0.015*AJ4)+(0.045*AG4) | CP4: =(0.055*BM4)+(0.055*BN4)+(0.035*BO4)+(0.035*BQ4)+(0.055*BH4)+(0.035*BI4)+(0.035*BG4) | CQ4: =CK4+CL4+CM4+CN4+CO4
